Workbook
Name NativeTimeline_Application_Date: #N/A
Name Slicer_Loan_Status: #N/A
Name Slicer_Region: #N/A

Sheet Loan_Data
A1: Loan_ID | B1: Customer_Name | C1: Age | D1: Employment_Type | E1: Monthly_Income | F1: Loan_Amount | G1: Loan_Term_Months | H1: Interest_Rate | I1: Loan_Purpose | J1: Credit_Score | K1: Application_Date | L1: Approval_Date | M1: Loan_Status | N1: EMI | O1: Region | P1: Branch | Q1: Repayment_Status | R1: Late_Payments | S1: Outstanding_Balance | T1: Risk Category
A2: LN10854 | B2: Chetna Saxena | C2: 35 | D2: Self-Employed | E2: 15700 | F2: 2000000 | G2: 48 | H2: 21.84 | I2: Vehicle Loan | J2: 450 | K2: 44859 | L2: 2022-10-30 | M2: Approved | N2: 62838.56 | O2: South | P2: Bangalore-Whitefield | Q2: On Track | R2: 1 | S2: 2000000 | T2: Very High Risk | U2: 2. Find and remove the duplicate Loan_ID records. Note how many duplicates you removed. | AM2: 16. Sort the data by Outstanding_Balance from largest to smallest. Which customer has the highest balance? | AV2: Chetna Saxena
A3: LN11033 | B3: Vinod Kaur | C3: 33 | D3: Business Owner | E3: 175715 | F3: 2000000 | G3: 12 | H3: 16.83 | I3: Medical | J3: 879 | K3: 44467 | L3: 2021-10-16 | M3: Approved | N3: 182248.19 | O3: Central | P3: Indore-Main | Q3: Defaulted | R3: 8 | S3: 2000000 | T3: Low Risk | AV3: Vinod Kaur
A4: LN11048 | B4: Vikram Mishra | C4: 40 | D4: Freelancer | E4: 68136 | F4: 2000000 | G4: 60 | H4: 7.85 | I4: Business Expansion | J4: 492 | K4: 44287 | L4: 2021-05-01 | M4: Approved | N4: 40409.37 | O4: South | P4: Hyderabad-Hitech | Q4: Defaulted | R4: 12 | S4: 2000000 | T4: Very High Risk | AV4: Vikram Mishra
A5: LN10668 | B5: Pooja Iyer | C5: 25 | D5: Self-Employed | E5: 98360 | F5: 2000000 | G5: 120 | H5: 10.12 | I5: Debt Consolidation | J5: 788 | K5: 45248 | L5: 2023-12-13 | M5: Pending | N5: 26563.23 | O5: Central | P5: Bhopal-Mp Nagar | Q5: Late | R5: 4 | S5: 1976093.1 | T5: Low Risk | AM5: 17. Filter Repayment_Status to show only Defaulted loans. How many are there? Now add a second filter to show defaults from the North region only.
A6: LN10299 | B6: Vikram Jain | C6: 54 | D6: Salaried | E6: 90978 | F6: 2000000 | G6: 60 | H6: 16.3 | I6: Business Expansion | J6: 748 | K6: 45167 | L6: 2023-09-06 | M6: Approved | N6: 48955.49 | O6: West | P6: Ahmedabad-Cg Road | Q6: On Track | R6: 2 | S6: 1955940.1 | T6: Medium Risk | AN6: Defaulted loans= | AO6: 112
A7: LN11104 | B7: Mohan Malhotra | C7: 58 | D7: Self-Employed | E7: 124468 | F7: 2000000 | G7: 36 | H7: 13.69 | I7: Business Expansion | J7: 515 | K7: 44740 | L7: 2022-07-24 | M7: Approved | N7: 68054.52 | O7: North | P7: Delhi-Connaught | Q7: Closed | R7: 0 | S7: 1877501.9 | T7: Very High Risk | AM7: Loan_ID | AN7: Customer_Name | AO7: Age | AP7: Employment_Type | AQ7: Monthly_Income | AR7: Loan_Amount | AS7: Loan_Term_Months | AT7: Interest_Rate | AU7: Loan_Purpose | AV7: Credit_Score | AW7: Application_Date | AX7: Approval_Date | AY7: Loan_Status | AZ7: EMI | BA7: Region | BB7: Branch | BC7: Repayment_Status | BD7: Late_Payments | BE7: Outstanding_Balance | BG7: Loan_ID | BH7: Customer_Name | BI7: Age | BJ7: Employment_Type | BK7: Monthly_Income | BL7: Loan_Amount | BM7: Loan_Term_Months | BN7: Interest_Rate | BO7: Loan_Purpose | BP7: Credit_Score | BQ7: Application_Date | BR7: Approval_Date | BS7: Loan_Status | BT7: EMI | BU7: Region | BV7: Branch | BW7: Repayment_Status | BX7: Late_Payments | BY7: Outstanding_Balance
A8: LN11156 | B8: Ganesh Mishra | C8: 56 | D8: Self-Employed | E8: 187306 | F8: 2000000 | G8: 12 | H8: 20.93 | I8: Agriculture | J8: 521 | K8: 45228 | L8: 2023-11-19 | M8: Approved | N8: 186160.36 | O8: West | P8: Pune-Shivajinagar | Q8: Closed | R8: 0 | S8: 1832455.7 | T8: Very High Risk | BC8: Defaulted | BU8: North | BW8: Defaulted
A9: LN10511 | B9: Anita Saxena | C9: 65 | D9: Self-Employed | E9: 87806 | F9: 2000000 | G9: 36 | H9: 12.76 | I9: Medical | J9: 615 | K9: 44687 | L9: 2022-05-17 | M9: Approved | N9: 67156.94 | O9: North | P9: Chandigarh-Main | Q9: On Track | R9: 0 | S9: 1818676.3 | T9: High Risk
A10: LN10384 | B10: Mohan Iyer | C10: 30 | D10: Self-Employed | E10: 21867 | F10: 2000000 | G10: 60 | H10: 16.28 | I10: Personal | J10: 537 | K10: 45173 | L10: 2023-09-11 | M10: Rejected | N10: 48934.16 | O10: South | P10: Bangalore-Koramangala | Q10: Closed | R10: 1 | S10: 1779796.3 | T10: Very High Risk | AM10: Loan_ID | AN10: Customer_Name | AO10: Age | AP10: Employment_Type | AQ10: Monthly_Income | AR10: Loan_Amount | AS10: Loan_Term_Months | AT10: Interest_Rate | AU10: Loan_Purpose | AV10: Credit_Score | AW10: Application_Date | AX10: Approval_Date | AY10: Loan_Status | AZ10: EMI | BA10: Region | BB10: Branch | BC10: Repayment_Status | BD10: Late_Payments | BE10: Outstanding_Balance | BG10: Loan_ID | BH10: Customer_Name | BI10: Age | BJ10: Employment_Type | BK10: Monthly_Income | BL10: Loan_Amount | BM10: Loan_Term_Months | BN10: Interest_Rate | BO10: Loan_Purpose | BP10: Credit_Score | BQ10: Application_Date | BR10: Approval_Date | BS10: Loan_Status | BT10: EMI | BU10: Region | BV10: Branch | BW10: Repayment_Status | BX10: Late_Payments | BY10: Outstanding_Balance
A11: LN10696 | B11: Vinod Mishra | C11: 35 | D11: Government Employee | E11: 180098 | F11: 2000000 | G11: 120 | H11: 9.76 | I11: Personal | J11: 744 | K11: 45212 | L11: 2023-10-21 | M11: Approved | N11: 26165.06 | O11: East | P11: Kolkata-Salt Lake | Q11: On Track | R11: 1 | S11: 1740965.9 | T11: Medium Risk | AM11: LN11033 | AN11: Vinod Kaur | AO11: 33 | AP11: Business Owner | AQ11: 175715 | AR11: 2000000 | AS11: 12 | AT11: 16.83 | AU11: Medical | AV11: 879 | AW11: 44467 | AX11: 2021-10-16 | AY11: Approved | AZ11: 182248.19 | BA11: Central | BB11: Indore-Main | BC11: Defaulted | BD11: 8 | BE11: 2000000 | BG11: LN10306 | BH11: Komal Nair | BI11: 39 | BJ11: Self-Employed | BK11: 248648 | BL11: 500000 | BM11: 48 | BN11: 11.32 | BO11: Vehicle Loan | BP11: 377 | BQ11: 45026 | BR11: 2023-05-07 | BS11: Approved | BT11: 13000.6 | BU11: North | BV11: Chandigarh-Main | BW11: Defaulted | BX11: 10 | BY11: 488299.46
A12: LN10446 | B12: Amit Joshi | C12: 28 | D12: Government Employee | E12: 113600 | F12: 2000000 | G12: 36 | H12: 7.73 | I12: Agriculture | J12: 382 | K12: 44778 | L12: 2022-08-21 | M12: Rejected | N12: 62423.92 | O12: North | P12: Delhi-Connaught | Q12: Closed | R12: 0 | S12: 1719092.4 | T12: Very High Risk | AM12: LN11048 | AN12: Vikram Mishra | AO12: 40 | AP12: Freelancer | AQ12: 68136 | AR12: 2000000 | AS12: 60 | AT12: 7.85 | AU12: Business Expansion | AV12: 492 | AW12: 44287 | AX12: 2021-05-01 | AY12: Approved | AZ12: 40409.37 | BA12: South | BB12: Hyderabad-Hitech | BC12: Defaulted | BD12: 12 | BE12: 2000000 | BG12: LN10100 | BH12: Nisha Mishra | BI12: 59 | BJ12: Salaried | BK12: 107259 | BL12: 500000 | BM12: 24 | BN12: 12 | BO12: Agriculture | BP12: 338 | BQ12: 44381 | BR12: 2021-07-26 | BS12: Rejected | BT12: 23536.74 | BU12: North | BV12: Noida-Sector18 | BW12: Defaulted | BX12: 4 | BY12: 457633.87
A13: LN10283 | B13: Manoj Singh | C13: 62 | D13: Government Employee | E13: 47301 | F13: 2000000 | G13: 180 | H13: 14.13 | I13: Education | J13: 810 | K13: 45083 | L13: 2023-07-05 | M13: Approved | N13: 26809.74 | O13: North | P13: Chandigarh-Main | Q13: Late | R13: 11 | S13: 1710454.8 | T13: Low Risk | AM13: LN10380 | AN13: Tarun Chatterjee | AO13: 37 | AP13: Government Employee | AQ13: 87319 | AR13: 2000000 | AS13: 12 | AT13: 16.57 | AU13: Debt Consolidation | AV13: 330 | AW13: 44896 | AX13: 2022-12-16 | AY13: Rejected | AZ13: 182001.62 | BA13: Central | BB13: Nagpur-Dharampeth | BC13: Defaulted | BD13: 3 | BE13: 1672397.1 | BG13: LN10912 | BH13: Sunita Deshpande | BI13: 62 | BJ13: Salaried | BK13: 66491 | BL13: 400000 | BM13: 24 | BN13: 13.91 | BO13: Agriculture | BP13: 502 | BQ13: 45194 | BR13: 2023-10-07 | BS13: Approved | BT13: 19188.15 | BU13: North | BV13: Chandigarh-Main | BW13: Defaulted | BX13: 9 | BY13: 296383.99
A14: LN10239 | B14: Ganesh Chaudhary | C14: 32 | D14: Freelancer | E14: 34322 | F14: 2000000 | G14: 12 | H14: 11.78 | I14: Medical | J14: 567 | K14: 44965 | L14: 2023-02-16 | M14: Approved | N14: 177491.81 | O14: North | P14: Delhi-Connaught | Q14: Late | R14: 5 | S14: 1680514.7 | T14: High Risk | AM14: LN10382 | AN14: Komal Joshi | AO14: 59 | AP14: Government Employee | AQ14: 194319 | AR14: 2000000 | AS14: 48 | AT14: 20.01 | AU14: Business Expansion | AV14: 836 | AW14: 44520 | AX14: 2021-12-03 | AY14: Approved | AZ14: 60871.38 | BA14: South | BB14: Hyderabad-Hitech | BC14: Defaulted | BD14: 12 | BE14: 1506941.8 | BG14: LN10210 | BH14: Vinod Joshi | BI14: 46 | BJ14: Government Employee | BK14: 125326 | BL14: 250000 | BM14: 240 | BN14: 17.4 | BO14: Agriculture | BP14: 374 | BQ14: 44733 | BR14: 2022-06-30 | BS14: Approved | BT14: 3743.24 | BU14: North | BV14: Chandigarh-Main | BW14: Defaulted | BX14: 1 | BY14: 239893.25
A15: LN10392 | B15: Ajay Mehta | C15: 32 | D15: Self-Employed | E15: 61888 | F15: 2000000 | G15: 12 | H15: 13.58 | I15: Business Expansion | J15: 756 | K15: 44612 | L15: 2022-02-23 | M15: Approved | N15: 179179.24 | O15: East | P15: Kolkata-Salt Lake | Q15: On Track | R15: 0 | S15: 1677477.4 | T15: Low Risk | AM15: LN11127 | AN15: Anita Menon | AO15: 32 | AP15: Business Owner | AQ15: 40586 | AR15: 2000000 | AS15: 60 | AT15: 11.99 | AU15: Vehicle Loan | AV15: 378 | AW15: 44332 | AX15: 2021-06-12 | AY15: Approved | AZ15: 44478.79 | BA15: South | BB15: Bangalore-Koramangala | BC15: Defaulted | BD15: 0 | BE15: 1399536.3 | BG15: LN11189 | BH15: Geeta Patel | BI15: 43 | BJ15: Self-Employed | BK15: 144073 | BL15: 300000 | BM15: 120 | BN15: 13.81 | BO15: Home Purchase | BP15: 831 | BQ15: 45070 | BR15: 2023-06-20 | BS15: Approved | BT15: 4623.78 | BU15: North | BV15: Delhi-Connaught | BW15: Defaulted | BX15: 11 | BY15: 233417.57
A16: LN10101 | B16: Naveen Nayak | C16: 51 | D16: Government Employee | E16: 160310 | F16: 2000000 | G16: 12 | H16: 14.02 | I16: Personal | J16: 629 | K16: 44323 | L16: 2021-05-24 | M16: Approved | N16: 179593.06 | O16: Central | P16: Raipur-Main | Q16: On Track | R16: 2 | S16: 1676732.5 | T16: High Risk | AM16: LN10495 | AN16: Amit Shah | AO16: 57 | AP16: Business Owner | AQ16: 246918 | AR16: 1500000 | AS16: 36 | AT16: 14.63 | AU16: Education | AV16: 619 | AW16: 45201 | AX16: 2023-10-26 | AY16: Approved | AZ16: 51726.62 | BA16: West | BB16: Ahmedabad-CG Road | BC16: Defaulted | BD16: 12 | BE16: 1174122.3 | BG16: LN10562 | BH16: Rani Malhotra | BI16: 25 | BJ16: Business Owner | BK16: 248061 | BL16: 200000 | BM16: 48 | BN16: 10.15 | BO16: Agriculture | BP16: 302 | BQ16: 44288 | BR16: 2021-04-18 | BS16: Rejected | BT16: 5086.94 | BU16: North | BV16: Chandigarh-Main | BW16: Defaulted | BX16: 5 | BY16: 181687.02
A17: LN10380 | B17: Tarun Chatterjee | C17: 37 | D17: Government Employee | E17: 87319 | F17: 2000000 | G17: 12 | H17: 16.57 | I17: Debt Consolidation | J17: 330 | K17: 44896 | L17: 2022-12-16 | M17: Rejected | N17: 182001.62 | O17: Central | P17: Nagpur-Dharampeth | Q17: Defaulted | R17: 3 | S17: 1672397.1 | T17: Very High Risk | AM17: LN10026 | AN17: Suresh Jain | AO17: 57 | AP17: Freelancer | AQ17: 177702 | AR17: 1500000 | AS17: 36 | AT17: 20.92 | AU17: Personal | AV17: 466 | AW17: 44877 | AX17: 2022-12-10 | AY17: Pending | AZ17: 56451.01 | BA17: South | BB17: Hyderabad-Hitech | BC17: Defaulted | BD17: 0 | BE17: 941135 | BG17: LN10969 | BH17: Kiran Patel | BI17: 57 | BJ17: Freelancer | BK17: 161537 | BL17: 1000000 | BM17: 12 | BN17: 20.49 | BO17: Agriculture | BP17: 451 | BQ17: 44762 | BR17: 2022-08-10 | BS17: Approved | BT17: 92869.18 | BU17: North | BV17: Noida-Sector18 | BW17: Defaulted | BX17: 1 | BY17: 80595.12
A18: LN10972 | B18: Manoj Gupta | C18: 34 | D18: Self-Employed | F18: 2000000 | G18: 36 | H18: 19.62 | I18: Home Purchase | J18: 806 | K18: 45023 | L18: 2023-04-28 | M18: Rejected | N18: 73940.49 | O18: North | P18: Noida-Sector18 | Q18: Late | R18: 1 | S18: 1600721.4 | T18: Low Risk | AM18: LN10275 | AN18: Bhavna Nayak | AO18: 44 | AP18: Government Employee | AQ18: 22554 | AR18: 1000000 | AS18: 36 | AT18: 14.5 | AU18: Agriculture | AV18: 415 | AW18: 44732 | AX18: 2022-07-13 | AY18: Approved | AZ18: 34420.98 | BA18: West | BB18: Ahmedabad-CG Road | BC18: Defaulted | BD18: 0 | BE18: 876084.47 | BG18: LN10991 | BH18: Harish Mehta | BI18: 40 | BJ18: Government Employee | BK18: 31685 | BL18: 150000 | BM18: 36 | BN18: 16.59 | BO18: Medical | BP18: 749 | BQ18: 45279 | BR18: 2023-12-31 | BS18: Approved | BT18: 5317.35 | BU18: North | BV18: Gurgaon-CyberCity | BW18: Defaulted | BX18: 1 | BY18: 78215.77
A19: LN10700 | B19: Pallavi Nair | C19: 34 | D19: Self-Employed | E19: 140940 | F19: 2000000 | G19: 180 | H19: 19.32 | I19: Business Expansion | J19: 639 | K19: 44744 | L19: 2022-07-25 | M19: Approved | N19: 34125.38 | O19: West | P19: Mumbai-Bandra | Q19: Late | R19: 3 | S19: 1570020.2 | T19: High Risk | U19: 3. The Customer_Name column has extra spaces at the start and end of some names. Use TRIM to fix this, then paste the cleaned values back into the column. | AM19: LN10259 | AN19: Manoj Kaur | AO19: 46 | AP19: Salaried | AQ19: 167836 | AR19: 1500000 | AS19: 48 | AT19: 12.48 | AU19: Personal | AV19: 847 | AW19: 44545 | AX19: 2022-01-13 | AY19: Approved | AZ19: 39855.19 | BA19: West | BB19: Pune-Shivajinagar | BC19: Defaulted | BD19: 8 | BE19: 818476.25 | BG19: LN10369 | BH19: Lakshmi Jain | BI19: 49 | BJ19: Freelancer | BK19: 242496 | BL19: 75000 | BM19: 48 | BN19: 18.34 | BO19: Home Purchase | BP19: 691 | BQ19: 44850 | BR19: 2022-11-05 | BS19: Approved | BT19: 2216.47 | BU19: North | BV19: Noida-Sector18 | BW19: Defaulted | BX19: 8 | BY19: 71010.35
A20: LN10720 | B20: Tarun Kapoor | C20: 28 | D20: Salaried | E20: 52387 | F20: 2000000 | G20: 60 | H20: 15.43 | I20: Vehicle Loan | J20: 810 | K20: 44802 | L20: 2022-09-06 | M20: Approved | N20: 48032.48 | O20: North | P20: Gurgaon-Cybercity | Q20: Late | R20: 5 | S20: 1567707.7 | T20: Low Risk | AM20: LN10515 | AN20: Komal Shah | AO20: 62 | AP20: Freelancer | AQ20: 222360 | AR20: 1000000 | AS20: 36 | AT20: 7.54 | AU20: Personal | AV20: 612 | AW20: 44520 | AX20: 2021-11-30 | AY20: Approved | AZ20: 31124.59 | BA20: East | BB20: Guwahati-Main | BC20: Defaulted | BD20: 1 | BE20: 803915.08 | BG20: LN11106 | BH20: Siddharth Deshpande | BI20: 55 | BJ20: Self-Employed | BK20: 190047 | BL20: 1000000 | BM20: 240 | BN20: 17.4 | BO20: Personal | BP20: 531 | BQ20: 44869 | BR20: 2022-11-23 | BS20: Rejected | BT20: 14972.95 | BU20: North | BV20: Gurgaon-CyberCity | BW20: Defaulted | BX20: 7 | BY20: 70179.8
A21: LN11187 | B21: Ganesh Kulkarni | C21: 23 | D21: Government Employee | E21: 51514 | F21: 2000000 | G21: 120 | H21: 10.32 | I21: Education | J21: 520 | K21: 44347 | L21: 2021-06-10 | M21: Approved | N21: 26785.82 | O21: Central | P21: Lucknow-Hazratganj | Q21: On Track | R21: 2 | S21: 1566069.7 | T21: Very High Risk | AM21: LN10845 | AN21: Meena Kaur | AO21: 61 | AP21: Freelancer | AQ21: 152207 | AR21: 1500000 | AS21: 48 | AT21: 8.35 | AU21: Agriculture | AV21: 558 | AW21: 44505 | AX21: 2021-11-09 | AY21: Approved | AZ21: 36866.32 | BA21: West | BB21: Pune-Shivajinagar | BC21: Defaulted | BD21: 11 | BE21: 803226.55 | BG21: LN10314 | BH21: Tarun Singh | BI21: 58 | BJ21: Self-Employed | BK21: 29656 | BL21: 100000 | BM21: 60 | BN21: 20.88 | BO21: Debt Consolidation | BP21: 877 | BQ21: 45116 | BR21: 2023-07-31 | BS21: Approved | BT21: 2698.59 | BU21: North | BV21: Noida-Sector18 | BW21: Defaulted | BX21: 1 | BY21: 68426.5
A22: LN11167 | B22: Rajesh Patel | C22: 64 | D22: Salaried | E22: 241200 | F22: 2000000 | G22: 12 | H22: 8.71 | I22: Education | J22: 899 | K22: 45181 | L22: 2023-10-10 | M22: Approved | N22: 174634.11 | O22: North | P22: Delhi-Connaught | Q22: Late | R22: 11 | S22: 1528487.9 | T22: Low Risk | AM22: LN11080 | AN22: Suresh Tiwari | AO22: 35 | AP22: Salaried | AQ22: 248651 | AR22: 1000000 | AS22: 12 | AT22: 7.64 | AU22: Medical | AV22: 583 | AW22: 44648 | AX22: 2022-04-19 | AY22: Approved | AZ22: 86822.07 | BA22: East | BB22: Patna-Boring Road | BC22: Defaulted | BD22: 3 | BE22: 765580.41 | BG22: LN10583 | BH22: Deepa Patel | BI22: 36 | BJ22: Freelancer | BK22: 34514 | BL22: 150000 | BM22: 48 | BN22: 9.88 | BO22: Business Expansion | BP22: 364 | BQ22: 44246 | BR22: 2021-03-12 | BS22: Approved | BT22: 3795.75 | BU22: North | BV22: Delhi-Connaught | BW22: Defaulted | BX22: 7 | BY22: 57763.27
A23: LN10006 | B23: Tarun Chaudhary | C23: 65 | D23: Business Owner | E23: 235948 | F23: 2000000 | G23: 12 | H23: 10.82 | I23: Home Purchase | J23: 623 | K23: 44841 | L23: 2022-10-16 | M23: Approved | N23: 176595.44 | O23: West | P23: Pune-Shivajinagar | Q23: Grace Period | R23: 0 | S23: 1523192.3 | T23: High Risk | AM23: LN10252 | AN23: Nisha Kaur | AO23: 30 | AP23: Government Employee | AQ23: 245511 | AR23: 750000 | AS23: 12 | AT23: 10.02 | AU23: Personal | AV23: 359 | AW23: 44935 | AX23: 2023-02-03 | AY23: Approved | AZ23: 65943.89 | BA23: South | BB23: Bangalore-Koramangala | BC23: Defaulted | BD23: 7 | BE23: 750000 | BG23: LN10200 | BH23: Pallavi Deshpande | BI23: 37 | BJ23: Freelancer | BK23: 143308 | BL23: 100000 | BM23: 60 | BN23: 16.6 | BO23: Debt Consolidation | BP23: 762 | BQ23: 44766 | BR23: 2022-08-18 | BS23: Rejected | BT23: 2463.8 | BU23: North | BV23: Delhi-Connaught | BW23: Defaulted | BX23: 6 | BY23: 29042.56
A24: LN10382 | B24: Komal Joshi | C24: 59 | D24: Government Employee | E24: 194319 | F24: 2000000 | G24: 48 | H24: 20.01 | I24: Business Expansion | J24: 836 | K24: 44520 | L24: 2021-12-03 | M24: Approved | N24: 60871.38 | O24: South | P24: Hyderabad-Hitech | Q24: Defaulted | R24: 12 | S24: 1506941.8 | T24: Low Risk | AM24: LN10704 | AN24: Suresh Mishra | AO24: 53 | AP24: Business Owner | AQ24: 84573 | AR24: 2000000 | AS24: 24 | AT24: 18.94 | AU24: Education | AV24: 450 | AW24: 45176 | AX24: 2023-10-06 | AY24: Rejected | AZ24: 100758.94 | BA24: East | BB24: Kolkata-Salt Lake | BC24: Defaulted | BD24: 6 | BE24: 730437.36 | BG24: LN10195 | BH24: Jyoti Malhotra | BI24: 50 | BJ24: Freelancer | BK24: 58844 | BL24: 75000 | BM24: 12 | BN24: 19.04 | BO24: Personal | BP24: 599 | BQ24: 44788 | BR24: 2022-08-23 | BS24: Rejected | BT24: 6913.18 | BU24: North | BV24: Noida-Sector18 | BW24: Defaulted | BX24: 3 | BY24: 25225.1
A25: LN10469 | B25: Sanjay Mehta | C25: 58 | D25: Freelancer | E25: 103784 | F25: 1500000 | G25: 24 | H25: 18.11 | I25: Home Purchase | J25: 442 | K25: 45019 | L25: 2023-04-25 | M25: Approved | N25: 74965.9 | O25: Central | P25: Indore-Main | Q25: Closed | R25: 1 | S25: 1500000 | T25: Very High Risk | AM25: LN10917 | AN25: Suresh Chatterjee | AO25: 61 | AP25: Self-Employed | AQ25: 164686 | AR25: 1000000 | AS25: 36 | AT25: 12.19 | AU25: Personal | AV25: 705 | AW25: 44863 | AX25: 2022-11-17 | AY25: Approved | AZ25: 33305.13 | BA25: South | BB25: Bangalore-Whitefield | BC25: Defaulted | BD25: 9 | BE25: 700253.83 | BG25: LN10018 | BH25: Smita Banerjee | BI25: 49 | BJ25: Government Employee | BK25: 188505 | BL25: 1500000 | BM25: 180 | BN25: 9.74 | BO25: Business Expansion | BP25: 522 | BQ25: 44321 | BR25: 2021-05-31 | BS25: Pending | BT25: 15881.33 | BU25: North | BV25: Chandigarh-Main | BW25: Defaulted | BX25: 11 | BY25: 0
A26: LN10580 | B26: Chetna Shah | C26: 26 | D26: Government Employee | E26: 48619 | F26: 1500000 | G26: 24 | H26: 9.35 | I26: Personal | J26: 835 | K26: 45288 | L26: 2024-01-19 | M26: Rejected | N26: 68768.24 | O26: East | P26: Kolkata-Salt Lake | Q26: On Track | R26: 2 | S26: 1500000 | T26: Low Risk | AM26: LN10582 | AN26: Jyoti Shetty | AO26: 55 | AP26: Salaried | AQ26: 246683 | AR26: 1500000 | AS26: 48 | AT26: 8.18 | AU26: Debt Consolidation | AV26: 845 | AW26: 44595 | AX26: 2022-02-16 | AY26: Approved | AZ26: 36746.25 | BA26: West | BB26: Pune-Shivajinagar | BC26: Defaulted | BD26: 0 | BE26: 673209.38 | BG26: LN10197 | BH26: Chetna Verma | BI26: 41 | BJ26: Salaried | BK26: 132894 | BL26: 200000 | BM26: 84 | BN26: 20 | BO26: Vehicle Loan | BP26: 749 | BQ26: 44915 | BR26: 2023-01-19 | BS26: Approved | BT26: 4441.24 | BU26: North | BV26: Delhi-Dwarka | BW26: Defaulted | BX26: 3 | BY26: 0
A27: LN11020 | B27: Smita Dubey | C27: 31 | D27: Self-Employed | E27: 208425 | F27: 2000000 | G27: 120 | H27: 13.58 | I27: Home Purchase | J27: 442 | K27: 45015 | L27: 2023-04-13 | M27: Approved | N27: 30550.22 | O27: East | P27: Patna-Boring Road | Q27: On Track | R27: 2 | S27: 1477591.2 | T27: Very High Risk | AM27: LN10739 | AN27: Pallavi Joshi | AO27: 54 | AP27: Salaried | AQ27: 180528 | AR27: 750000 | AS27: 120 | AT27: 19.72 | AU27: Business Expansion | AV27: 866 | AW27: 44388 | AX27: 2021-07-14 | AY27: Rejected | AZ27: 14355.21 | BA27: South | BB27: Chennai-Adyar | BC27: Defaulted | BD27: 3 | BE27: 607883.42 | BG27: LN10211 | BH27: Amit Reddy | BI27: 47 | BJ27: Government Employee | BK27: 90101 | BL27: 1000000 | BM27: 240 | BN27: 18.62 | BO27: Debt Consolidation | BP27: 711 | BQ27: 44509 | BR27: 2021-11-20 | BS27: Rejected | BT27: 15911.88 | BU27: North | BV27: Chandigarh-Main | BW27: Defaulted | BX27: 8 | BY27: 0
A28: LN10930 | B28: Smita Pillai | C28: 58 | D28: Business Owner | E28: 249158 | F28: 1500000 | G28: 36 | H28: 10.24 | I28: Education | J28: 511 | K28: 45289 | L28: 2024-01-20 | M28: Rejected | N28: 48569.97 | O28: East | P28: Kolkata-Salt Lake | Q28: Late | R28: 1 | S28: 1456287 | T28: Very High Risk | AM28: LN10306 | AN28: Komal Nair | AO28: 39 | AP28: Self-Employed | AQ28: 248648 | AR28: 500000 | AS28: 48 | AT28: 11.32 | AU28: Vehicle Loan | AV28: 377 | AW28: 45026 | AX28: 2023-05-07 | AY28: Approved | AZ28: 13000.6 | BA28: North | BB28: Chandigarh-Main | BC28: Defaulted | BD28: 10 | BE28: 488299.46 | BG28: LN10216 | BH28: Chetna Sharma | BI28: 24 | BJ28: Salaried | BK28: 79107 | BL28: 50000 | BM28: 180 | BN28: 12.78 | BO28: Education | BP28: 483 | BQ28: 45055 | BR28: 2023-05-19 | BS28: Approved | BT28: 625.4 | BU28: North | BV28: Chandigarh-Main | BW28: Defaulted | BX28: 12 | BY28: 0
A29: LN10342 | B29: Sarala Reddy | C29: 23 | D29: Freelancer | E29: 152358 | F29: 2000000 | G29: 24 | H29: 9.01 | I29: Education | J29: 386 | K29: 44778 | L29: 2022-08-22 | M29: Approved | N29: 91378.66 | O29: West | P29: Pune-Shivajinagar | Q29: Late | R29: 3 | S29: 1424314.4 | T29: Very High Risk | AM29: LN10100 | AN29: Nisha Mishra | AO29: 59 | AP29: Salaried | AQ29: 107259 | AR29: 500000 | AS29: 24 | AT29: 12 | AU29: Agriculture | AV29: 338 | AW29: 44381 | AX29: 2021-07-26 | AY29: Rejected | AZ29: 23536.74 | BA29: North | BB29: Noida-Sector18 | BC29: Defaulted | BD29: 4 | BE29: 457633.87 | BG29: LN10406 | BH29: Madhuri Chatterjee | BI29: 42 | BJ29: Self-Employed | BK29: 216714 | BL29: 75000 | BM29: 240 | BN29: 17.31 | BO29: Education | BP29: 510 | BQ29: 45266 | BR29: 2023-12-12 | BS29: Pending | BT29: 1117.82 | BU29: North | BV29: Gurgaon-CyberCity | BW29: Defaulted | BX29: 6 | BY29: 0
A30: LN11011 | B30: Sunil Rao | C30: 23 | D30: Self-Employed | E30: 226347 | F30: 2000000 | G30: 24 | H30: 11.02 | I30: Education | J30: 682 | K30: 44375 | L30: 2021-07-28 | M30: Pending | N30: 93234.25 | O30: North | P30: Delhi-Dwarka | Q30: Late | R30: 9 | S30: 1412624.2 | T30: Medium Risk | U30: 4. Employment_Type has inconsistent casing — some entries are in all caps, others are all lowercase. Use PROPER to standardise them, then paste the values back. | AM30: LN10578 | AN30: Pooja Jain | AO30: 34 | AP30: Salaried | AQ30: 228983 | AR30: 750000 | AS30: 60 | AT30: 19.22 | AU30: Personal | AV30: 539 | AW30: 45206 | AX30: 2023-11-01 | AY30: Approved | AZ30: 19546.32 | BA30: West | BB30: Pune-Shivajinagar | BC30: Defaulted | BD30: 0 | BE30: 450941.3 | BG30: LN10527 | BH30: Ashok Nair | BI30: 35 | BJ30: Business Owner | BK30: 62357 | BL30: 100000 | BM30: 240 | BN30: 19.43 | BO30: Personal | BP30: 897 | BQ30: 44566 | BR30: 2022-01-21 | BS30: Pending | BT30: 1654.2 | BU30: North | BV30: Chandigarh-Main | BW30: Defaulted | BX30: 12 | BY30: 0
A31: LN10772 | B31: Lakshmi Rao | C31: 49 | D31: Freelancer | E31: 163547 | F31: 2000000 | G31: 84 | H31: 11.68 | I31: Home Purchase | J31: 810 | K31: 45268 | L31: 2023-12-20 | M31: Approved | N31: 34964.12 | O31: South | P31: Hyderabad-Hitech | Q31: On Track | R31: 2 | S31: 1402113.6 | T31: Low Risk | AM31: LN10462 | AN31: Madhuri Rao | AO31: 52 | AP31: Government Employee | AQ31: 192814 | AR31: 500000 | AS31: 60 | AT31: 14.05 | AU31: Medical | AV31: 367 | AW31: 44997 | AX31: 2023-03-20 | AY31: Rejected | AZ31: 11647.09 | BA31: South | BB31: Hyderabad-Hitech | BC31: Defaulted | BD31: 1 | BE31: 447588.09 | BG31: LN10607 | BH31: Rekha Kaur | BI31: 26 | BJ31: Government Employee | BK31: 116301 | BL31: 150000 | BM31: 180 | BN31: 9.08 | BO31: Agriculture | BP31: 611 | BQ31: 44560 | BR31: 2022-01-03 | BS31: Approved | BT31: 1528.55 | BU31: North | BV31: Delhi-Dwarka | BW31: Defaulted | BX31: 1 | BY31: 0
A32: LN11127 | B32: Anita Menon | C32: 32 | D32: Business Owner | E32: 40586 | F32: 2000000 | G32: 60 | H32: 11.99 | I32: Vehicle Loan | J32: 378 | K32: 44332 | L32: 2021-06-12 | M32: Approved | N32: 44478.79 | O32: South | P32: Bangalore-Koramangala | Q32: Defaulted | R32: 0 | S32: 1399536.3 | T32: Very High Risk | AM32: LN10491 | AN32: Anil Tiwari | AO32: 53 | AP32: Business Owner | AQ32: 215492 | AR32: 1500000 | AS32: 60 | AT32: 18.47 | AU32: Debt Consolidation | AV32: 664 | AW32: 45244 | AX32: 2023-11-25 | AY32: Approved | AZ32: 38474.7 | BA32: West | BB32: Surat-Ring Road | BC32: Defaulted | BD32: 6 | BE32: 426555.87 | BG32: LN10657 | BH32: Abhishek Nair | BI32: 51 | BJ32: Freelancer | BK32: 87146 | BL32: 1000000 | BM32: 180 | BN32: 12.83 | BO32: Vehicle Loan | BP32: 419 | BQ32: 45240 | BR32: 2023-11-20 | BS32: Approved | BT32: 12540.77 | BU32: North | BV32: Delhi-Connaught | BW32: Defaulted | BX32: 7 | BY32: 0
A33: LN10633 | B33: Rohit Jain | C33: 54 | D33: Freelancer | E33: 181456 | F33: 1500000 | G33: 84 | H33: 17.6 | I33: Debt Consolidation | J33: 734 | K33: 44937 | L33: 2023-02-03 | M33: Approved | N33: 31176.06 | O33: South | P33: Bangalore-Whitefield | Q33: On Track | R33: 1 | S33: 1387766.2 | T33: Medium Risk | AM33: LN10835 | AN33: Pooja Menon | AO33: 48 | AP33: Salaried | AQ33: 162392 | AR33: 2000000 | AS33: 84 | AT33: 11.29 | AU33: Medical | AV33: 721 | AW33: 44730 | AX33: 2022-06-22 | AY33: Approved | AZ33: 34550.59 | BA33: West | BB33: Ahmedabad-CG Road | BC33: Defaulted | BD33: 6 | BE33: 414127.92 | BG33: LN10804 | BH33: Deepa Menon | BI33: 30 | BJ33: Government Employee | BK33: 75433 | BL33: 200000 | BM33: 240 | BN33: 10.56 | BO33: Medical | BP33: 445 | BQ33: 45126 | BR33: 2023-07-25 | BS33: Approved | BT33: 2004.83 | BU33: North | BV33: Delhi-Dwarka | BW33: Defaulted | BX33: 11 | BY33: 0
A34: LN10279 | B34: Jyoti Dubey | C34: 42 | D34: Salaried | E34: 145383 | F34: 1500000 | G34: 12 | H34: 8.99 | I34: Debt Consolidation | J34: 336 | K34: 44820 | L34: 2022-10-05 | M34: Approved | N34: 131170.26 | O34: Central | P34: Lucknow-Hazratganj | Q34: On Track | R34: 0 | S34: 1381946.8 | T34: Very High Risk | AM34: LN10942 | AN34: Pallavi Yadav | AO34: 64 | AP34: Government Employee | AQ34: 151293 | AR34: 500000 | AS34: 60 | AT34: 18.52 | AU34: Education | AV34: 635 | AW34: 44267 | AX34: 2021-04-07 | AY34: Approved | AZ34: 12838.58 | BA34: West | BB34: Pune-Shivajinagar | BC34: Defaulted | BD34: 10 | BE34: 396007.5 | BG34: LN10986 | BH34: Rajesh Malhotra | BI34: 48 | BJ34: Freelancer | BK34: 87898 | BL34: 150000 | BM34: 180 | BN34: 11.17 | BO34: Home Purchase | BP34: 704 | BQ34: 44653 | BR34: 2022-04-07 | BS34: Approved | BT34: 1720.94 | BU34: North | BV34: Gurgaon-CyberCity | BW34: Defaulted | BX34: 2 | BY34: 0
A35: LN11079 | B35: Kavitha Joshi | C35: 33 | D35: Salaried | E35: 109721 | F35: 2000000 | G35: 12 | H35: 8.1 | I35: Vehicle Loan | J35: 584 | K35: 44457 | L35: 2021-10-16 | M35: Approved | N35: 174069.34 | O35: North | P35: Chandigarh-Main | Q35: On Track | R35: 2 | S35: 1373350.4 | T35: High Risk | AM35: LN10817 | AN35: Ramesh Deshpande | AO35: 39 | AP35: Business Owner | AQ35: 234154 | AR35: 750000 | AS35: 60 | AT35: 20.71 | AU35: Medical | AV35: 548 | AW35: 44433 | AX35: 2021-09-19 | AY35: Approved | AZ35: 20167.86 | BA35: East | BB35: Kolkata-Salt Lake | BC35: Defaulted | BD35: 7 | BE35: 386978.52
A36: LN11135 | B36: Madhuri Shetty | C36: 26 | D36: Freelancer | E36: 95841 | F36: 1500000 | G36: 60 | H36: 13.4 | I36: Home Purchase | J36: 591 | K36: 44478 | L36: 2021-10-28 | M36: Approved | N36: 34437.54 | O36: East | P36: Kolkata-Salt Lake | Q36: On Track | R36: 2 | S36: 1345031.1 | T36: High Risk | AM36: LN10603 | AN36: Pallavi Joshi | AO36: 56 | AP36: Business Owner | AQ36: 17237 | AR36: 2000000 | AS36: 60 | AT36: 11.59 | AU36: Medical | AV36: 713 | AW36: 44221 | AX36: 2021-02-12 | AZ36: 44075.63 | BA36: West | BB36: Surat-Ring Road | BC36: Defaulted | BD36: 12 | BE36: 373609.25
A37: LN10637 | B37: Kiran Kapoor | C37: 22 | D37: Business Owner | E37: 33308 | F37: 2000000 | G37: 120 | H37: 15.11 | I37: Business Expansion | J37: 741 | K37: 44472 | L37: 2021-10-12 | M37: Rejected | N37: 32401.85 | O37: South | P37: Bangalore-Whitefield | Q37: On Track | R37: 1 | S37: 1329281.7 | T37: Medium Risk | AM37: LN11124 | AN37: Usha Sharma | AO37: 49 | AP37: Salaried | AQ37: 34950 | AR37: 2000000 | AS37: 60 | AT37: 15.26 | AU37: Debt Consolidation | AV37: 316 | AW37: 44301 | AX37: 2021-05-03 | AY37: Approved | AZ37: 47853.25 | BA37: Central | BB37: Nagpur-Dharampeth | BC37: Defaulted | BD37: 12 | BE37: 363418.85
A38: LN11055 | B38: Rajesh Iyer | C38: 53 | D38: Self-Employed | E38: 33928 | F38: 1500000 | G38: 60 | H38: 11.01 | I38: Debt Consolidation | J38: 610 | K38: 44588 | L38: 2022-01-30 | M38: Approved | N38: 32621.12 | O38: South | P38: Kochi-Mg Road | Q38: Grace Period | R38: 2 | S38: 1323845.9 | T38: High Risk | AM38: LN10034 | AN38: Mohan Mehta | AO38: 23 | AP38: Salaried | AQ38: 79184 | AR38: 400000 | AS38: 24 | AT38: 14.1 | AU38: Personal | AV38: 693 | AW38: 44208 | AX38: 2021-02-08 | AY38: Approved | AZ38: 19224.06 | BA38: West | BB38: Ahmedabad-CG Road | BC38: Defaulted | BD38: 3 | BE38: 330793.38
A39: LN10712 | B39: Usha Tiwari | C39: 65 | D39: Freelancer | E39: 160268 | F39: 1500000 | G39: 60 | H39: 20.83 | I39: Business Expansion | J39: 532 | K39: 45265 | L39: 2023-12-20 | M39: Approved | N39: 40436.73 | O39: West | P39: Mumbai-Bandra | Q39: On Track | R39: 1 | S39: 1318034.7 | T39: Very High Risk | AM39: LN10354 | AN39: Amit Saxena | AO39: 60 | AP39: Self-Employed | AQ39: 112359 | AR39: 2000000 | AS39: 24 | AT39: 11.11 | AU39: Agriculture | AV39: 393 | AW39: 44319 | AX39: 2021-05-07 | AY39: Approved | AZ39: 93317.85 | BA39: Central | BB39: Nagpur-Dharampeth | BC39: Defaulted | BD39: 12 | BE39: 320278.7
A40: LN10324 | B40: Mohan Singh | C40: 60 | D40: Government Employee | E40: 150217 | F40: 1500000 | G40: 48 | H40: 16.42 | I40: Home Purchase | J40: 668 | K40: 44762 | L40: 2022-08-16 | M40: Approved | N40: 42833.77 | O40: South | P40: Bangalore-Koramangala | Q40: Late | R40: 2 | S40: 1307248 | T40: Medium Risk | AM40: LN10724 | AN40: Kiran Kaur | AO40: 26 | AP40: Self-Employed | AQ40: 116770 | AR40: 400000 | AS40: 24 | AT40: 12.56 | AU40: Agriculture | AV40: 847 | AW40: 44418 | AX40: 2021-08-25 | AY40: Approved | AZ40: 18934.17 | BA40: West | BB40: Mumbai-Andheri | BC40: Defaulted | BD40: 1 | BE40: 314796.23
...

Sheet Reference_Tables
A1: RISK BAND MAPPING TABLE
A2: Credit Score Range | B2: Risk Category | C2: Risk Code | D2: Action Required
A3: 750 – 900 | B3: Low Risk | C3: LR | D3: Approve – Standard Terms
A4: 650 – 749 | B4: Medium Risk | C4: MR | D4: Approve – With Conditions
A5: 550 – 649 | B5: High Risk | C5: HR | D5: Review – Senior Approval
A6: 300 – 549 | B6: Very High Risk | C6: VHR | D6: Reject or Collateral Required
A7: Not Available | B7: Unclassified | C7: UC | D7: Pending Review
A10: BRANCH CODE REFERENCE TABLE
A11: Branch_Name | B11: Branch_Code | C11: Region | D11: Manager
A12: Delhi-Connaught | B12: BR-DL01 | C12: North | D12: Ananya Sharma
A13: Delhi-Dwarka | B13: BR-DL02 | C13: North | D13: Vikram Malhotra
A14: Noida-Sector18 | B14: BR-NR01 | C14: North | D14: Priyanka Gupta
A15: Gurgaon-CyberCity | B15: BR-GR01 | C15: North | D15: Rahul Kapoor
A16: Chandigarh-Main | B16: BR-CH01 | C16: North | D16: Deepak Nair
A17: Bangalore-Koramangala | B17: BR-BL01 | C17: South | D17: Santhosh Rao
A18: Bangalore-Whitefield | B18: BR-BL02 | C18: South | D18: Meena Iyer
A19: Chennai-Adyar | B19: BR-CH01 | C19: South | D19: Arvind Pillai
A20: Hyderabad-Hitech | B20: BR-HY01 | C20: South | D20: Lakshmi Reddy
A21: Kochi-MG Road | B21: BR-KC01 | C21: South | D21: Suresh Menon
A22: Kolkata-Park Street | B22: BR-KO01 | C22: East | D22: Debashis Das
... A36: Lucknow-Hazratganj | B36: BR-LK01 | C36: Central | D36: Sandeep Saxena

Sheet Task_Workspace
A1: TASK WORKSPACE – Students will work here | B1: Days to Approval | C1: Loan Age in Months | D1: Maturity Date | E1: Is_Matured | F1: DTI Ratio | G1: DTI Flag | H1: Risk Category | I1: Risk Code | J1: Branch Manager
B2: =DATEDIF(Loan_Data!K:K,Loan_Data!L:L,"D") -> 5 | C2: =DATEDIF(LoanData[[#This Row],[Approval_Date]],TODAY(),"M") -> 45 | D2: =EDATE(LoanData[[#This Row],[Approval_Date]],LoanData[[#This Row],[Loan_Term_Months]]) -> 46325 | E2: =IF(D2<TODAY(),"YES","NO") -> NO | F2: =IFERROR(LoanData[[#This Row],[EMI]]/LoanData[[#This Row],[Monthly_Income]]*100," ") -> 400.24561 | G2: {=_xlfn.IFS(F2>40, "High DTI Risk",F2>=25, "Moderate DTI",F2<25, "Low DTI")} -> High DTI Risk | H2: {=_xlfn.IFS(AND(LoanData[[#This Row],[Credit_Score]]>=750,LoanData[[#This Row],[Credit_Score]]<=900),"Low Risk", AND(LoanData[[#This Row],[Credit_Score]]>=650,LoanData[[#This Row],[Credit_Score]]<=749),"Medium Risk", AND(LoanData[[#This Row],[Credit_Score]]>=550,LoanData[[#This Row],[Credit_Score]]<=649),"High Risk", AND(LoanData[[#This Row],[Credit_Score]]>=300,LoanData[[#This Row],[Credit_Score]]<=549),"Very High Risk", LoanData[[#This Row],[Credit_Score]]="Not Available","Unclassified")} -> Very High Risk | I2: =_xlfn.XLOOKUP(H2,Reference_Tables!$B$2:$B$7,Reference_Tables!$C$2:$C$7,,0,1) -> VHR | J2: =INDEX(Reference_Tables!$D$11:$D$36,MATCH(LoanData[[#This Row],[Branch]],Reference_Tables!$A$11:$A$36,0)) -> Meena Iyer
A3: Use this sheet for calculated columns, classifications, and formulas. | B3: =DATEDIF(Loan_Data!K:K,Loan_Data!L:L,"D") -> 18 | C3: =DATEDIF(LoanData[[#This Row],[Approval_Date]],TODAY(),"M") -> 58 | D3: =EDATE(LoanData[[#This Row],[Approval_Date]],LoanData[[#This Row],[Loan_Term_Months]]) -> 44850 | E3: =IF(D3<TODAY(),"YES","NO") -> YES | F3: =IFERROR(LoanData[[#This Row],[EMI]]/LoanData[[#This Row],[Monthly_Income]]*100," ") -> 103.71806 | G3: {=_xlfn.IFS(F3>40, "High DTI Risk",F3>=25, "Moderate DTI",F3<25, "Low DTI")} -> High DTI Risk | H3: {=_xlfn.IFS(AND(LoanData[[#This Row],[Credit_Score]]>=750,LoanData[[#This Row],[Credit_Score]]<=900),"Low Risk", AND(LoanData[[#This Row],[Credit_Score]]>=650,LoanData[[#This Row],[Credit_Score]]<=749),"Medium Risk", AND(LoanData[[#This Row],[Credit_Score]]>=550,LoanData[[#This Row],[Credit_Score]]<=649),"High Risk", AND(LoanData[[#This Row],[Credit_Score]]>=300,LoanData[[#This Row],[Credit_Score]]<=549),"Very High Risk", LoanData[[#This Row],[Credit_Score]]="Not Available","Unclassified")} -> Low Risk | I3: =_xlfn.XLOOKUP(H3,Reference_Tables!$B$2:$B$7,Reference_Tables!$C$2:$C$7,,0,1) -> LR | J3: =INDEX(Reference_Tables!$D$11:$D$36,MATCH(LoanData[[#This Row],[Branch]],Reference_Tables!$A$11:$A$36,0)) -> Ravi Verma
B4: =DATEDIF(Loan_Data!K:K,Loan_Data!L:L,"D") -> 30 | C4: =DATEDIF(LoanData[[#This Row],[Approval_Date]],TODAY(),"M") -> 63 | D4: =EDATE(LoanData[[#This Row],[Approval_Date]],LoanData[[#This Row],[Loan_Term_Months]]) -> 46143 | E4: =IF(D4<TODAY(),"YES","NO") -> YES | F4: =IFERROR(LoanData[[#This Row],[EMI]]/LoanData[[#This Row],[Monthly_Income]]*100," ") -> 59.30693 | G4: {=_xlfn.IFS(F4>40, "High DTI Risk",F4>=25, "Moderate DTI",F4<25, "Low DTI")} -> High DTI Risk | H4: {=_xlfn.IFS(AND(LoanData[[#This Row],[Credit_Score]]>=750,LoanData[[#This Row],[Credit_Score]]<=900),"Low Risk", AND(LoanData[[#This Row],[Credit_Score]]>=650,LoanData[[#This Row],[Credit_Score]]<=749),"Medium Risk", AND(LoanData[[#This Row],[Credit_Score]]>=550,LoanData[[#This Row],[Credit_Score]]<=649),"High Risk", AND(LoanData[[#This Row],[Credit_Score]]>=300,LoanData[[#This Row],[Credit_Score]]<=549),"Very High Risk", LoanData[[#This Row],[Credit_Score]]="Not Available","Unclassified")} -> Very High Risk | I4: =_xlfn.XLOOKUP(H4,Reference_Tables!$B$2:$B$7,Reference_Tables!$C$2:$C$7,,0,1) -> VHR | J4: =INDEX(Reference_Tables!$D$11:$D$36,MATCH(LoanData[[#This Row],[Branch]],Reference_Tables!$A$11:$A$36,0)) -> Lakshmi Reddy
B5: =DATEDIF(Loan_Data!K:K,Loan_Data!L:L,"D") -> 25 | C5: =DATEDIF(LoanData[[#This Row],[Approval_Date]],TODAY(),"M") -> 32 | D5: =EDATE(LoanData[[#This Row],[Approval_Date]],LoanData[[#This Row],[Loan_Term_Months]]) -> 48926 | E5: =IF(D5<TODAY(),"YES","NO") -> NO | F5: =IFERROR(LoanData[[#This Row],[EMI]]/LoanData[[#This Row],[Monthly_Income]]*100," ") -> 27.006131 | G5: {=_xlfn.IFS(F5>40, "High DTI Risk",F5>=25, "Moderate DTI",F5<25, "Low DTI")} -> Moderate DTI | H5: {=_xlfn.IFS(AND(LoanData[[#This Row],[Credit_Score]]>=750,LoanData[[#This Row],[Credit_Score]]<=900),"Low Risk", AND(LoanData[[#This Row],[Credit_Score]]>=650,LoanData[[#This Row],[Credit_Score]]<=749),"Medium Risk", AND(LoanData[[#This Row],[Credit_Score]]>=550,LoanData[[#This Row],[Credit_Score]]<=649),"High Risk", AND(LoanData[[#This Row],[Credit_Score]]>=300,LoanData[[#This Row],[Credit_Score]]<=549),"Very High Risk", LoanData[[#This Row],[Credit_Score]]="Not Available","Unclassified")} -> Low Risk | I5: =_xlfn.XLOOKUP(H5,Reference_Tables!$B$2:$B$7,Reference_Tables!$C$2:$C$7,,0,1) -> LR | J5: =INDEX(Reference_Tables!$D$11:$D$36,MATCH(LoanData[[#This Row],[Branch]],Reference_Tables!$A$11:$A$36,0)) -> Suman Tiwari
B6: =DATEDIF(Loan_Data!K:K,Loan_Data!L:L,"D") -> 8 | C6: =DATEDIF(LoanData[[#This Row],[Approval_Date]],TODAY(),"M") -> 35 | D6: =EDATE(LoanData[[#This Row],[Approval_Date]],LoanData[[#This Row],[Loan_Term_Months]]) -> 47002 | E6: =IF(D6<TODAY(),"YES","NO") -> NO | F6: =IFERROR(LoanData[[#This Row],[EMI]]/LoanData[[#This Row],[Monthly_Income]]*100," ") -> 53.810251 | G6: {=_xlfn.IFS(F6>40, "High DTI Risk",F6>=25, "Moderate DTI",F6<25, "Low DTI")} -> High DTI Risk | H6: {=_xlfn.IFS(AND(LoanData[[#This Row],[Credit_Score]]>=750,LoanData[[#This Row],[Credit_Score]]<=900),"Low Risk", AND(LoanData[[#This Row],[Credit_Score]]>=650,LoanData[[#This Row],[Credit_Score]]<=749),"Medium Risk", AND(LoanData[[#This Row],[Credit_Score]]>=550,LoanData[[#This Row],[Credit_Score]]<=649),"High Risk", AND(LoanData[[#This Row],[Credit_Score]]>=300,LoanData[[#This Row],[Credit_Score]]<=549),"Very High Risk", LoanData[[#This Row],[Credit_Score]]="Not Available","Unclassified")} -> Medium Risk | I6: =_xlfn.XLOOKUP(H6,Reference_Tables!$B$2:$B$7,Reference_Tables!$C$2:$C$7,,0,1) -> MR | J6: =INDEX(Reference_Tables!$D$11:$D$36,MATCH(LoanData[[#This Row],[Branch]],Reference_Tables!$A$11:$A$36,0)) -> Hetal Patel
B7: =DATEDIF(Loan_Data!K:K,Loan_Data!L:L,"D") -> 26 | C7: =DATEDIF(LoanData[[#This Row],[Approval_Date]],TODAY(),"M") -> 48 | D7: =EDATE(LoanData[[#This Row],[Approval_Date]],LoanData[[#This Row],[Loan_Term_Months]]) -> 45862 | E7: =IF(D7<TODAY(),"YES","NO") -> YES | F7: =IFERROR(LoanData[[#This Row],[EMI]]/LoanData[[#This Row],[Monthly_Income]]*100," ") -> 54.676318 | G7: {=_xlfn.IFS(F7>40, "High DTI Risk",F7>=25, "Moderate DTI",F7<25, "Low DTI")} -> High DTI Risk | H7: {=_xlfn.IFS(AND(LoanData[[#This Row],[Credit_Score]]>=750,LoanData[[#This Row],[Credit_Score]]<=900),"Low Risk", AND(LoanData[[#This Row],[Credit_Score]]>=650,LoanData[[#This Row],[Credit_Score]]<=749),"Medium Risk", AND(LoanData[[#This Row],[Credit_Score]]>=550,LoanData[[#This Row],[Credit_Score]]<=649),"High Risk", AND(LoanData[[#This Row],[Credit_Score]]>=300,LoanData[[#This Row],[Credit_Score]]<=549),"Very High Risk", LoanData[[#This Row],[Credit_Score]]="Not Available","Unclassified")} -> Very High Risk | I7: =_xlfn.XLOOKUP(H7,Reference_Tables!$B$2:$B$7,Reference_Tables!$C$2:$C$7,,0,1) -> VHR | J7: =INDEX(Reference_Tables!$D$11:$D$36,MATCH(LoanData[[#This Row],[Branch]],Reference_Tables!$A$11:$A$36,0)) -> Ananya Sharma
B8: =DATEDIF(Loan_Data!K:K,Loan_Data!L:L,"D") -> 21 | C8: =DATEDIF(LoanData[[#This Row],[Approval_Date]],TODAY(),"M") -> 32 | D8: =EDATE(LoanData[[#This Row],[Approval_Date]],LoanData[[#This Row],[Loan_Term_Months]]) -> 45615 | E8: =IF(D8<TODAY(),"YES","NO") -> YES | F8: =IFERROR(LoanData[[#This Row],[EMI]]/LoanData[[#This Row],[Monthly_Income]]*100," ") -> 99.388359 | G8: {=_xlfn.IFS(F8>40, "High DTI Risk",F8>=25, "Moderate DTI",F8<25, "Low DTI")} -> High DTI Risk | H8: {=_xlfn.IFS(AND(LoanData[[#This Row],[Credit_Score]]>=750,LoanData[[#This Row],[Credit_Score]]<=900),"Low Risk", AND(LoanData[[#This Row],[Credit_Score]]>=650,LoanData[[#This Row],[Credit_Score]]<=749),"Medium Risk", AND(LoanData[[#This Row],[Credit_Score]]>=550,LoanData[[#This Row],[Credit_Score]]<=649),"High Risk", AND(LoanData[[#This Row],[Credit_Score]]>=300,LoanData[[#This Row],[Credit_Score]]<=549),"Very High Risk", LoanData[[#This Row],[Credit_Score]]="Not Available","Unclassified")} -> Very High Risk | I8: =_xlfn.XLOOKUP(H8,Reference_Tables!$B$2:$B$7,Reference_Tables!$C$2:$C$7,,0,1) -> VHR | J8: =INDEX(Reference_Tables!$D$11:$D$36,MATCH(LoanData[[#This Row],[Branch]],Reference_Tables!$A$11:$A$36,0)) -> Sachin Deshpande
B9: =DATEDIF(Loan_Data!K:K,Loan_Data!L:L,"D") -> 11 | C9: =DATEDIF(LoanData[[#This Row],[Approval_Date]],TODAY(),"M") -> 51 | D9: =EDATE(LoanData[[#This Row],[Approval_Date]],LoanData[[#This Row],[Loan_Term_Months]]) -> 45794 | E9: =IF(D9<TODAY(),"YES","NO") -> YES | F9: =IFERROR(LoanData[[#This Row],[EMI]]/LoanData[[#This Row],[Monthly_Income]]*100," ") -> 76.483315 | G9: {=_xlfn.IFS(F9>40, "High DTI Risk",F9>=25, "Moderate DTI",F9<25, "Low DTI")} -> High DTI Risk | H9: {=_xlfn.IFS(AND(LoanData[[#This Row],[Credit_Score]]>=750,LoanData[[#This Row],[Credit_Score]]<=900),"Low Risk", AND(LoanData[[#This Row],[Credit_Score]]>=650,LoanData[[#This Row],[Credit_Score]]<=749),"Medium Risk", AND(LoanData[[#This Row],[Credit_Score]]>=550,LoanData[[#This Row],[Credit_Score]]<=649),"High Risk", AND(LoanData[[#This Row],[Credit_Score]]>=300,LoanData[[#This Row],[Credit_Score]]<=549),"Very High Risk", LoanData[[#This Row],[Credit_Score]]="Not Available","Unclassified")} -> High Risk | I9: =_xlfn.XLOOKUP(H9,Reference_Tables!$B$2:$B$7,Reference_Tables!$C$2:$C$7,,0,1) -> HR | J9: =INDEX(Reference_Tables!$D$11:$D$36,MATCH(LoanData[[#This Row],[Branch]],Reference_Tables!$A$11:$A$36,0)) -> Deepak Nair
B10: =DATEDIF(Loan_Data!K:K,Loan_Data!L:L,"D") -> 7 | C10: =DATEDIF(LoanData[[#This Row],[Approval_Date]],TODAY(),"M") -> 35 | D10: =EDATE(LoanData[[#This Row],[Approval_Date]],LoanData[[#This Row],[Loan_Term_Months]]) -> 47007 | E10: =IF(D10<TODAY(),"YES","NO") -> NO | F10: =IFERROR(LoanData[[#This Row],[EMI]]/LoanData[[#This Row],[Monthly_Income]]*100," ") -> 223.78086 | G10: {=_xlfn.IFS(F10>40, "High DTI Risk",F10>=25, "Moderate DTI",F10<25, "Low DTI")} -> High DTI Risk | H10: {=_xlfn.IFS(AND(LoanData[[#This Row],[Credit_Score]]>=750,LoanData[[#This Row],[Credit_Score]]<=900),"Low Risk", AND(LoanData[[#This Row],[Credit_Score]]>=650,LoanData[[#This Row],[Credit_Score]]<=749),"Medium Risk", AND(LoanData[[#This Row],[Credit_Score]]>=550,LoanData[[#This Row],[Credit_Score]]<=649),"High Risk", AND(LoanData[[#This Row],[Credit_Score]]>=300,LoanData[[#This Row],[Credit_Score]]<=549),"Very High Risk", LoanData[[#This Row],[Credit_Score]]="Not Available","Unclassified")} -> Very High Risk | I10: =_xlfn.XLOOKUP(H10,Reference_Tables!$B$2:$B$7,Reference_Tables!$C$2:$C$7,,0,1) -> VHR | J10: =INDEX(Reference_Tables!$D$11:$D$36,MATCH(LoanData[[#This Row],[Branch]],Reference_Tables!$A$11:$A$36,0)) -> Santhosh Rao
B11: =DATEDIF(Loan_Data!K:K,Loan_Data!L:L,"D") -> 8 | C11: =DATEDIF(LoanData[[#This Row],[Approval_Date]],TODAY(),"M") -> 33 | D11: =EDATE(LoanData[[#This Row],[Approval_Date]],LoanData[[#This Row],[Loan_Term_Months]]) -> 48873 | E11: =IF(D11<TODAY(),"YES","NO") -> NO | F11: =IFERROR(LoanData[[#This Row],[EMI]]/LoanData[[#This Row],[Monthly_Income]]*100," ") -> 14.528235 | G11: {=_xlfn.IFS(F11>40, "High DTI Risk",F11>=25, "Moderate DTI",F11<25, "Low DTI")} -> Low DTI | H11: {=_xlfn.IFS(AND(LoanData[[#This Row],[Credit_Score]]>=750,LoanData[[#This Row],[Credit_Score]]<=900),"Low Risk", AND(LoanData[[#This Row],[Credit_Score]]>=650,LoanData[[#This Row],[Credit_Score]]<=749),"Medium Risk", AND(LoanData[[#This Row],[Credit_Score]]>=550,LoanData[[#This Row],[Credit_Score]]<=649),"High Risk", AND(LoanData[[#This Row],[Credit_Score]]>=300,LoanData[[#This Row],[Credit_Score]]<=549),"Very High Risk", LoanData[[#This Row],[Credit_Score]]="Not Available","Unclassified")} -> Medium Risk | I11: =_xlfn.XLOOKUP(H11,Reference_Tables!$B$2:$B$7,Reference_Tables!$C$2:$C$7,,0,1) -> MR | J11: =INDEX(Reference_Tables!$D$11:$D$36,MATCH(LoanData[[#This Row],[Branch]],Reference_Tables!$A$11:$A$36,0)) -> Puja Chatterjee
B12: =DATEDIF(Loan_Data!K:K,Loan_Data!L:L,"D") -> 16 | C12: =DATEDIF(LoanData[[#This Row],[Approval_Date]],TODAY(),"M") -> 47 | D12: =EDATE(LoanData[[#This Row],[Approval_Date]],LoanData[[#This Row],[Loan_Term_Months]]) -> 45890 | E12: =IF(D12<TODAY(),"YES","NO") -> YES | F12: =IFERROR(LoanData[[#This Row],[EMI]]/LoanData[[#This Row],[Monthly_Income]]*100," ") -> 54.950634 | G12: {=_xlfn.IFS(F12>40, "High DTI Risk",F12>=25, "Moderate DTI",F12<25, "Low DTI")} -> High DTI Risk | H12: {=_xlfn.IFS(AND(LoanData[[#This Row],[Credit_Score]]>=750,LoanData[[#This Row],[Credit_Score]]<=900),"Low Risk", AND(LoanData[[#This Row],[Credit_Score]]>=650,LoanData[[#This Row],[Credit_Score]]<=749),"Medium Risk", AND(LoanData[[#This Row],[Credit_Score]]>=550,LoanData[[#This Row],[Credit_Score]]<=649),"High Risk", AND(LoanData[[#This Row],[Credit_Score]]>=300,LoanData[[#This Row],[Credit_Score]]<=549),"Very High Risk", LoanData[[#This Row],[Credit_Score]]="Not Available","Unclassified")} -> Very High Risk | I12: =_xlfn.XLOOKUP(H12,Reference_Tables!$B$2:$B$7,Reference_Tables!$C$2:$C$7,,0,1) -> VHR | J12: =INDEX(Reference_Tables!$D$11:$D$36,MATCH(LoanData[[#This Row],[Branch]],Reference_Tables!$A$11:$A$36,0)) -> Ananya Sharma
B13: =DATEDIF(Loan_Data!K:K,Loan_Data!L:L,"D") -> 29 | C13: =DATEDIF(LoanData[[#This Row],[Approval_Date]],TODAY(),"M") -> 37 | D13: =EDATE(LoanData[[#This Row],[Approval_Date]],LoanData[[#This Row],[Loan_Term_Months]]) -> 50591 | E13: =IF(D13<TODAY(),"YES","NO") -> NO | F13: =IFERROR(LoanData[[#This Row],[EMI]]/LoanData[[#This Row],[Monthly_Income]]*100," ") -> 56.679013 | G13: {=_xlfn.IFS(F13>40, "High DTI Risk",F13>=25, "Moderate DTI",F13<25, "Low DTI")} -> High DTI Risk | H13: {=_xlfn.IFS(AND(LoanData[[#This Row],[Credit_Score]]>=750,LoanData[[#This Row],[Credit_Score]]<=900),"Low Risk", AND(LoanData[[#This Row],[Credit_Score]]>=650,LoanData[[#This Row],[Credit_Score]]<=749),"Medium Risk", AND(LoanData[[#This Row],[Credit_Score]]>=550,LoanData[[#This Row],[Credit_Score]]<=649),"High Risk", AND(LoanData[[#This Row],[Credit_Score]]>=300,LoanData[[#This Row],[Credit_Score]]<=549),"Very High Risk", LoanData[[#This Row],[Credit_Score]]="Not Available","Unclassified")} -> Low Risk | I13: =_xlfn.XLOOKUP(H13,Reference_Tables!$B$2:$B$7,Reference_Tables!$C$2:$C$7,,0,1) -> LR | J13: =INDEX(Reference_Tables!$D$11:$D$36,MATCH(LoanData[[#This Row],[Branch]],Reference_Tables!$A$11:$A$36,0)) -> Deepak Nair
B14: =DATEDIF(Loan_Data!K:K,Loan_Data!L:L,"D") -> 8 | C14: =DATEDIF(LoanData[[#This Row],[Approval_Date]],TODAY(),"M") -> 42 | D14: =EDATE(LoanData[[#This Row],[Approval_Date]],LoanData[[#This Row],[Loan_Term_Months]]) -> 45338 | E14: =IF(D14<TODAY(),"YES","NO") -> YES | F14: =IFERROR(LoanData[[#This Row],[EMI]]/LoanData[[#This Row],[Monthly_Income]]*100," ") -> 517.13714 | G14: {=_xlfn.IFS(F14>40, "High DTI Risk",F14>=25, "Moderate DTI",F14<25, "Low DTI")} -> High DTI Risk | H14: {=_xlfn.IFS(AND(LoanData[[#This Row],[Credit_Score]]>=750,LoanData[[#This Row],[Credit_Score]]<=900),"Low Risk", AND(LoanData[[#This Row],[Credit_Score]]>=650,LoanData[[#This Row],[Credit_Score]]<=749),"Medium Risk", AND(LoanData[[#This Row],[Credit_Score]]>=550,LoanData[[#This Row],[Credit_Score]]<=649),"High Risk", AND(LoanData[[#This Row],[Credit_Score]]>=300,LoanData[[#This Row],[Credit_Score]]<=549),"Very High Risk", LoanData[[#This Row],[Credit_Score]]="Not Available","Unclassified")} -> High Risk | I14: =_xlfn.XLOOKUP(H14,Reference_Tables!$B$2:$B$7,Reference_Tables!$C$2:$C$7,,0,1) -> HR | J14: =INDEX(Reference_Tables!$D$11:$D$36,MATCH(LoanData[[#This Row],[Branch]],Reference_Tables!$A$11:$A$36,0)) -> Ananya Sharma
B15: =DATEDIF(Loan_Data!K:K,Loan_Data!L:L,"D") -> 3 | C15: =DATEDIF(LoanData[[#This Row],[Approval_Date]],TODAY(),"M") -> 53 | D15: =EDATE(LoanData[[#This Row],[Approval_Date]],LoanData[[#This Row],[Loan_Term_Months]]) -> 44980 | E15: =IF(D15<TODAY(),"YES","NO") -> YES | F15: =IFERROR(LoanData[[#This Row],[EMI]]/LoanData[[#This Row],[Monthly_Income]]*100," ") -> 289.52178 | G15: {=_xlfn.IFS(F15>40, "High DTI Risk",F15>=25, "Moderate DTI",F15<25, "Low DTI")} -> High DTI Risk | H15: {=_xlfn.IFS(AND(LoanData[[#This Row],[Credit_Score]]>=750,LoanData[[#This Row],[Credit_Score]]<=900),"Low Risk", AND(LoanData[[#This Row],[Credit_Score]]>=650,LoanData[[#This Row],[Credit_Score]]<=749),"Medium Risk", AND(LoanData[[#This Row],[Credit_Score]]>=550,LoanData[[#This Row],[Credit_Score]]<=649),"High Risk", AND(LoanData[[#This Row],[Credit_Score]]>=300,LoanData[[#This Row],[Credit_Score]]<=549),"Very High Risk", LoanData[[#This Row],[Credit_Score]]="Not Available","Unclassified")} -> Low Risk | I15: =_xlfn.XLOOKUP(H15,Reference_Tables!$B$2:$B$7,Reference_Tables!$C$2:$C$7,,0,1) -> LR | J15: =INDEX(Reference_Tables!$D$11:$D$36,MATCH(LoanData[[#This Row],[Branch]],Reference_Tables!$A$11:$A$36,0)) -> Puja Chatterjee
... B1201: =DATEDIF(Loan_Data!K:K,Loan_Data!L:L,"D") -> 17 | C1201: =DATEDIF(LoanData[[#This Row],[Approval_Date]],TODAY(),"M") -> 59 | D1201: =EDATE(LoanData[[#This Row],[Approval_Date]],LoanData[[#This Row],[Loan_Term_Months]]) -> 48107 | E1201: =IF(D1201<TODAY(),"YES","NO") -> NO | F1201: =IFERROR(LoanData[[#This Row],[EMI]]/LoanData[[#This Row],[Monthly_Income]]*100," ") -> 0.52784372 | G1201: {=_xlfn.IFS(F1201>40, "High DTI Risk",F1201>=25, "Moderate DTI",F1201<25, "Low DTI")} -> Low DTI | H1201: {=_xlfn.IFS(AND(LoanData[[#This Row],[Credit_Score]]>=750,LoanData[[#This Row],[Credit_Score]]<=900),"Low Risk", AND(LoanData[[#This Row],[Credit_Score]]>=650,LoanData[[#This Row],[Credit_Score]]<=749),"Medium Risk", AND(LoanData[[#This Row],[Credit_Score]]>=550,LoanData[[#This Row],[Credit_Score]]<=649),"High Risk", AND(LoanData[[#This Row],[Credit_Score]]>=300,LoanData[[#This Row],[Credit_Score]]<=549),"Very High Risk", LoanData[[#This Row],[Credit_Score]]="Not Available","Unclassified")} -> Low Risk | I1201: =_xlfn.XLOOKUP(H1201,Reference_Tables!$B$2:$B$7,Reference_Tables!$C$2:$C$7,,0,1) -> LR | J1201: =INDEX(Reference_Tables!$D$11:$D$36,MATCH(LoanData[[#This Row],[Branch]],Reference_Tables!$A$11:$A$36,0)) -> Kavita Joshi

Sheet Pivot_Analysis
B2: 20. Loan Exposure by Region: Total Loan_Amount and Outstanding_Balance per Region. Which region has the highest total exposure?
H3: West
B5: Region | C5: Sum of Loan_Amount | D5: Sum of Outstanding_Balance
B6: Central | C6: 123625000 | D6: 49514738
B7: East | C7: 139425000 | D7: 51660457
B8: North | C8: 137400000 | D8: 55554824
B9: South | C9: 145300000 | D9: 54658363
B10: West | C10: 148725000 | D10: 55853474
B11: Grand Total | C11: 694475000 | D11: 2.6724186e+08
B13: 21. Risk Distribution: Count of loans and total Loan_Amount by Risk_Category. What percentage of the portfolio is High Risk or Very High Risk?
B15: Risk Distribution | C15: Count of Loan_ID | D15: Sum of Loan_Amount | H15: Loan_ID | I15: Loan_Amount
B16: High Risk | C16: 199 | D16: 0.15425321 | G16: High Risk | H16: 0.16583333 | I16: 0.15425321
B17: Low Risk | C17: 295 | D17: 0.25382483 | G17: Very High Risk | H17: 0.4025 | I17: 0.40530617
B18: Medium Risk | C18: 193 | D18: 0.15342525
B19: Unclassified | C19: 30 | D19: 0.03319054
B20: Very High Risk | C20: 483 | D20: 0.40530617
B21: Grand Total | C21: 1200 | D21: 1
B23: 22. Repayment by Employment Type: Cross-tab of Employment_Type vs Repayment_Status with Count of Loan_ID as values. Which employment type has the most defaults?
K24: Business Owner
B25: Count of Loan_ID | C25: Repayment_Status | K25: Government Employee
B26: Emplyoment_Type | C26: Closed | D26: Defaulted | E26: Grace Period | F26: Late | G26: On Track | H26: (blank) | I26: Grand Total | K26: Self-Employed
B27: Self-Employed | G27: 2 | I27: 2
B28: Business Owner | C28: 34 | D28: 25 | E28: 9 | F28: 60 | G28: 114 | I28: 242
B29: Freelancer | C29: 38 | D29: 18 | E29: 10 | F29: 55 | G29: 128 | H29: 2 | I29: 251
B30: Government Employee | C30: 28 | D30: 25 | E30: 7 | F30: 49 | G30: 135 | I30: 244
B31: Salaried | C31: 22 | D31: 19 | E31: 6 | F31: 58 | G31: 118 | I31: 223
B32: Salaried | G32: 1 | I32: 1
B33: Self-Employed | C33: 31 | D33: 25 | E33: 11 | F33: 55 | G33: 112 | H33: 3 | I33: 237
B34: Grand Total | C34: 153 | D34: 112 | E34: 43 | F34: 277 | G34: 610 | H34: 5 | I34: 1200
B36: 23. Branch Drill-Down: Nest Branch under Region in the rows. Collapse all regions and expand one at a time. Double-click a branch total to see the underlying detail — this is pivot drill-down.
B38: Branch Drill-Down
B39: Central
B40: Bhopal-Mp Nagar
B41: Indore-Main
B42: Lucknow-Hazratganj
B43: Nagpur-Dharampeth
B44: Raipur-Main
B45: East
B46: North
B47: South
...

Sheet Charts
B2: 25. From the Region pivot — a Clustered Column chart showing total loan amount by region.
B4: Region | C4: Sum of Loan_Amount
B5: Central | C5: 123625000
B6: East | C6: 139425000
B7: North | C7: 137400000
B8: South | C8: 145300000
B9: West | C9: 148725000
B10: Grand Total | C10: 694475000
B18: 26. From the Branch pivot — a horizontal Bar chart showing the top 10 branches by loan exposure.
B20: Branch | C20: Sum of Loan_Amount
B21: Ahmedabad-Cg Road | C21: 32825000
B22: Bangalore-Koramangala | C22: 34975000
B23: Bangalore-Whitefield | C23: 31850000
B24: Chandigarh-Main | C24: 32975000
B25: Gurgaon-Cybercity | C25: 29350000
B26: Hyderabad-Hitech | C26: 33025000
B27: Kolkata-Salt Lake | C27: 42325000
B28: Patna-Boring Road | C28: 33125000
B29: Pune-Shivajinagar | C29: 38800000
B30: Raipur-Main | C30: 30025000
B31: Grand Total | C31: 339275000
B36: 27. From the Monthly Trend pivot — a Line chart with markers showing how application volumes have moved month by month.
B56: 28. From the Risk Distribution pivot — a Pie or Doughnut chart showing the percentage split by risk category.
B58: Risk Category | C58: Sum of Loan_Amount
B59: High Risk | C59: 0.15425321
B60: Low Risk | C60: 0.25382483
B61: Medium Risk | C61: 0.15342525
B62: Unclassified | C62: 0.03319054
B63: Very High Risk | C63: 0.40530617
B64: Grand Total | C64: 1
B74: 29. Chart Decision: You need to show Repayment Status by Region to management. Would you use a Clustered Column chart or a Stacked Bar chart? Build both, then write 2–3 sentences explaining which one you chose and why. There is no single right answer — the reasoning matters.
B76: Count of Loan_ID | C76: Repayment Status
B77: Region | C77: Closed | D77: Defaulted | E77: Grace Period | F77: Late | G77: On Track | H77: (blank) | I77: Grand Total
B78: Central | C78: 29 | D78: 18 | E78: 14 | F78: 53 | G78: 113 | H78: 2 | I78: 229
B79: East | C79: 33 | D79: 19 | E79: 4 | F79: 56 | G79: 139 | I79: 251
B80: North | C80: 25 | D80: 24 | E80: 6 | F80: 50 | G80: 107 | H80: 2 | I80: 214
B81: South | C81: 38 | D81: 21 | E81: 9 | F81: 63 | G81: 120 | H81: 1 | I81: 252
B82: West | C82: 28 | D82: 30 | E82: 10 | F82: 55 | G82: 131 | I82: 254
B83: Grand Total | C83: 153 | D83: 112 | E83: 43 | F83: 277 | G83: 610 | H83: 5 | I83: 1200
B93: I would choose the Stacked Bar Chart because management often wants to see both the total exposure per region and the repayment mix inside that exposure.
...

Sheet Dashboard_Shell
B1: FinServe Lending Co. – Loan Portfolio Dashboard
B3: [ Pivot Chart 1: Loan Amount by Region ] | J3: [ Slicer: Region ]
B10: [ Pivot Chart 2: Risk Segmentation ] | J10: [ Slicer: Employment Type ]
B17: [ Pivot Chart 3: Repayment Status by Branch ] | J17: [ Timeline: Application_Date ]
